Workbook
Name _min2: #REF!
Name _min2: #REF!
Name _min2: #REF!
Name _min2: #REF!
Name _min2: #REF!
Name _min3: #REF!
Name _min3: #REF!
Name _min3: #REF!
Name _min3: #REF!
Name _min3: #REF!
Name _min4: #REF!
Name _min4: #REF!
Name _min4: #REF!
Name _min4: #REF!
Name _min4: #REF!
Name _min5: #REF!
Name _min5: #REF!
Name _min5: #REF!
Name _min5: #REF!
Name _min7: #REF!
Name _min7: #REF!
Name _min7: #REF!
Name _min7: #REF!
Name A: [1]LegerA!$C$7:$S$114
Name A: [1]LegerA!$C$7:$S$114
Name A: [1]LegerA!$C$7:$S$114
Name A: [1]LegerA!$C$7:$S$114
Name A: [2]LegerA!$C$7:$S$114
Name absen: '[1]Raport Ganjil'!$M$2
Name absen: '[1]Raport Ganjil'!$M$2
Name absen: '[1]Raport Ganjil'!$M$2
Name absen: '[1]Raport Ganjil'!$M$2
Name absen: '[2]Raport Ganjil'!$M$2
Name ABSEN2: #REF!
Name ABSEN2: #REF!
Name ABSEN2: #REF!
Name ABSEN2: #REF!
Name ABSEN2: #REF!
Name ABSEN4: #REF!
Name ABSEN4: #REF!
Name ABSEN4: #REF!
Name ABSEN4: #REF!
Name ABSEN4: #REF!
Name agmx1: [3]agm!$D$1:$G$65536
Name agmx1: [3]agm!$D$1:$G$65536
Name agmx1: [3]agm!$D$1:$G$65536
Name agmx1: [3]agm!$D$1:$G$65536
Name agmx1: [4]agm!$D$1:$G$65536
Name APD: #REF!
Name APD: #REF!
Name APD: #REF!
Name APD: #REF!
Name APD: #REF!
Name BACKUP.1: #REF!
Name BACKUP.1: #REF!
Name BACKUP.1: #REF!
Name BACKUP.1: #REF!
Name BACKUP.1: #REF!
Name bh: [5]Agama!$A$6:$K$45
Name bh: [5]Agama!$A$6:$K$45

Sheet VII
A1: PEMERINTAH DAERAH KABUPATEN KUNINGAN | H1: PEMERINTAH DAERAH KABUPATEN KUNINGAN
A2: DINAS PENDIDIKAN DAN KEBUDAYAAN | H2: DINAS PENDIDIKAN DAN KEBUDAYAAN
A3: SMPN 3 LURAGUNG | H3: SMPN 3 LURAGUNG
A4: Alamat : Jln. Abdi Praja No.01 Gunungkarung - Luragung | H4: Alamat : Jln. Abdi Praja No.01 Gunungkarung - Luragung
A6: ABSENSI KELAS VII A | H6: ABSENSI KELAS VII B
A7: TAHUN PELAJARAN 2025/2026 | H7: TAHUN PELAJARAN 2025/2026
A9: NO | B9: NIPD | C9: NISN | D9: NAMA PESERTA DIDIK | E9: JK | F9: KET | H9: NO | I9: NIPD | J9: NISN | K9: NAMA PESERTA DIDIK | L9: JK | M9: KET
A10: 1 | B10: 252607002 | D10: ADAM SHULBY | E10: L | H10: 1 | I10: 252607028 | K10: AJI NURSIDIK | L10: L
A11: 2 | B11: 252607004 | D11: AHMAD PAISAL | E11: L | H11: 2 | I11: 252607029 | K11: ALFIN ANGGARA | L11: L
A12: 3 | B12: 252607005 | D12: AMANDA KHOERIYAH | E12: P | H12: 3 | I12: 252607030 | K12: AUDITA FARIHAH KHOIRIYAH | L12: P
A13: 4 | B13: 252607006 | D13: ANASTASYA KHORUNISA | E13: P | H13: 4 | I13: 252607031 | K13: AYU ADILA MUKAROMAH | L13: P
A14: 5 | B14: 252607001 | D14: ANDHIKA CHANDRA KIRANA | E14: L | H14: 5 | I14: 252607032 | K14: CLARISYA SHEVA AUDYA | L14: P
A15: 6 | B15: 252607007 | D15: AZZAHRA RAHMADANI | E15: P | H15: 6 | I15: 252607033 | K15: EUIS NURHAMIDAH | L15: P
A16: 7 | B16: 252607009 | D16: GALUH BADRUTTAMAM | E16: L | H16: 7 | I16: 252607034 | K16: FAIZ ALFARIZI | L16: L
A17: 8 | B17: 252607010 | D17: ILHAM NURFADILLAH | E17: L | H17: 8 | I17: 252607035 | K17: INTAN FAIZA | L17: P
A18: 9 | B18: 252607011 | D18: ILMAN DZULFIKAR | E18: L | H18: 9 | I18: 252607036 | K18: KELVIN KURNIA MAULANA | L18: L
A19: 10 | B19: 252607012 | D19: MOCHAMAD AZRIEL PRATAMA | E19: L | H19: 10 | I19: 252607037 | K19: KENDI FABIANSYAH | L19: L
A20: 11 | B20: 252607013 | D20: MUHAMMAD VIKRI | E20: L | H20: 11 | I20: 252607038 | K20: KHOERUL NIJAM | L20: L
A21: 12 | B21: 252607014 | D21: NADIA OKTRIDEWI | E21: P | H21: 12 | I21: 252607039 | K21: KHUSLIFATUL HASANAH | L21: P
... A34: 25 | B34: 252607027 | D34: ZAIRA DWI MEY MEY | E34: P | H34: 25 | I34: 252607052 | K34: SIDQI AHSANI PUTRA | L34: L
A35: 26 | H35: 26 | I35: 252607053 | K35: TEGUH TRIGUNTARA | L35: L
A37: L | B37: =COUNTIF(E10:E34,"L") -> 13 | D37: Luragung, 14 Juli 2025 | H37: L | I37: =COUNTIF(L10:L35,"L") -> 15 | K37: Luragung, 14 Juli 2025
A38: P | B38: =COUNTIF(E10:E34,"P") -> 12 | D38: Wali Kelas, | H38: P | I38: =COUNTIF(L10:L35,"P") -> 11 | K38: Wali Kelas,
D40: HERMAN HERMAYANA, S.Pd., Gr | K40: SRI SITI NURHALIZA, S.Pd., Gr
D41: NIP. 19910602 202221 1 004 | K41: NIP. 19920323 202321 2 005
A42: PEMERINTAH DAERAH KABUPATEN KUNINGAN | H42: PEMERINTAH DAERAH KABUPATEN KUNINGAN
A43: DINAS PENDIDIKAN DAN KEBUDAYAAN | H43: DINAS PENDIDIKAN DAN KEBUDAYAAN
A44: SMPN 3 LURAGUNG | H44: SMPN 3 LURAGUNG
A45: Alamat : Jln. Abdi Praja No.01 Gunungkarung - Luragung | H45: Alamat : Jln. Abdi Praja No.01 Gunungkarung - Luragung
A47: ABSENSI KELAS VII C | H47: ABSENSI KELAS VII D
A48: TAHUN PELAJARAN 2025/2026 | H48: TAHUN PELAJARAN 2025/2026
A50: NO | B50: NIPD | C50: NISN | D50: NAMA PESERTA DIDIK | E50: JK | F50: KET | H50: NO | I50: NIPD | J50: NISN | K50: NAMA PESERTA DIDIK | L50: JK | M50: KET
A51: 1 | B51: 252607054 | D51: AISYA KIRANA | E51: P | H51: 1 | I51: 252607080 | K51: ADE KHOIRIL BAHRUDIN | L51: L
A52: 2 | B52: 252607055 | D52: AKMAL AMIRUL HAKIM | E52: L | H52: 2 | I52: 252607081 | K52: ADRIAN FRATAMA NUGRAHA | L52: L
A53: 3 | B53: 252607056 | D53: APRILIA KHOIRUNISA | E53: P | H53: 3 | I53: 252607082 | K53: AIDA DARMAYANTI | L53: P
A54: 4 | B54: 252607057 | D54: CECEP NUGI ANUGRAH | E54: L | H54: 4 | I54: 252607083 | K54: AIDIL FAZRI | L54: L
A55: 5 | B55: 252607058 | D55: CICIS LESINGIT | E55: P | H55: 5 | I55: 252607084 | K55: DAFA SUTRISNA | L55: L
A56: 6 | B56: 252607059 | D56: CIKA FITRIA | E56: P | H56: 6 | I56: 252607085 | K56: DAFFA RESTU PRATAMA | L56: L
A57: 7 | B57: 252607060 | D57: CITRA MILA RAHMAH | E57: P | H57: 7 | I57: 252607086 | K57: ELSA RAHMAWATI | L57: P
A58: 8 | B58: 252607061 | D58: DAFFA ARYA SYAHBANA | E58: L | H58: 8 | I58: 252607087 | K58: EVA DIANTIMALA | L58: P
...

Sheet VIII
A1: PEMERINTAH DAERAH KABUPATEN KUNINGAN | H1: PEMERINTAH DAERAH KABUPATEN KUNINGAN
A2: DINAS PENDIDIKAN DAN KEBUDAYAAN | H2: DINAS PENDIDIKAN DAN KEBUDAYAAN
A3: SMPN 3 LURAGUNG | H3: SMPN 3 LURAGUNG
A4: Alamat : Jln. Abdi Praja No.01 Gunungkarung - Luragung | H4: Alamat : Jln. Abdi Praja No.01 Gunungkarung - Luragung
A6: ABSENSI KELAS VIII A | H6: ABSENSI KELAS VIII B
A7: TAHUN PELAJARAN 2025/2026 | H7: TAHUN PELAJARAN 2025/2026
A9: NO | B9: NIPD | C9: NISN | D9: NAMA PESERTA DIDIK | E9: JK | F9: KET | H9: NO | I9: NIPD | J9: NISN | K9: NAMA PESERTA DIDIK | L9: JK | M9: KET
A10: 1 | B10: 242507033 | C10: 0111740793 | D10: ALDY FAHRIZAL | E10: L | H10: 1 | I10: 242507060 | J10: 0119822103 | K10: AIF FAHRUDIN | L10: L
A11: 2 | B11: 242507032 | C11: 0113170600 | D11: ALDA MUTHIA ZAHRA | E11: P | H11: 2 | I11: 242507061 | J11: 0112987017 | K11: ALFIN ALFARIDZI | L11: L
A12: 3 | B12: 242507034 | C12: 0112178893 | D12: ALGI KURNIAWAN | E12: L | H12: 3 | I12: 242507090 | J12: 0116250334 | K12: ALYA NUR LUTFIYAH ZAHRA | L12: P
A13: 4 | B13: 242507036 | C13: 3124228626 | D13: ANGGITA DWI CAHYA | E13: P | H13: 4 | I13: 242507005 | J13: 0119267536 | K13: DAVIN IMAM NAJIB | L13: L
A14: 5 | B14: 242507039 | C14: 0111141068 | D14: EMIN UMARUDIN | E14: L | H14: 5 | I14: 242507038 | J14: 0101543964 | K14: DESI YATI PUTRI | L14: P
A15: 6 | B15: 242507065 | C15: 0112027855 | D15: FITRI NURFADILAH | E15: P | H15: 6 | I15: 242507006 | J15: 0112972424 | K15: FABIAN AFIF AL MUNAWAR | L15: L
A16: 7 | B16: 242507097 | C16: 0122044898 | D16: HILDA FEBRI MAULIDIANSYAH | E16: P | H16: 7 | I16: 242507007 | J16: 0116212077 | K16: FATMA NABILAH | L16: P
A17: 8 | B17: 242507066 | C17: 0113490997 | D17: IKHSAN FAISAL ZIQRULOH | E17: L | H17: 8 | I17: 242507040 | J17: 0118678375 | K17: GALANG GALIH PRATAMA | L17: L
A18: 9 | B18: 242507098 | C18: 3112249544 | D18: INTAN NUR HAFIDZA | E18: P | H18: 9 | I18: 242507067 | J18: 0114533358 | K18: IMA MARDIANSAH | L18: P
A19: 10 | B19: 242507100 | C19: 0117859638 | D19: JESSEN MAULANA PRATAMA | E19: L | H19: 10 | I19: 242507045 | J19: 0122368407 | K19: LIA AULIA | L19: P
A20: 11 | B20: 242507043 | C20: 0115941935 | D20: JULIA PUTRI RESDIANA | E20: P | H20: 11 | I20: 242507070 | J20: 0122085016 | K20: MAWAR CAHYA FIRDANI | L20: P
A21: 12 | B21: 242507068 | C21: 0112339327 | D21: KHOERUL YAHYA GIBRANI | E21: L | H21: 12 | I21: 242507011 | J21: 0118024922 | K21: MUHAMAD ALDI REFIANSYAH | L21: L
... A38: 29 | B38: 242507116 | C38: 0106651015 | D38: WILLY NUGRAHA | E38: L | H38: 29 | I38: 242507086 | J38: 0118130917 | K38: YAYAT HIDAYAT | L38: L
H39: 30 | I39: 252608106 | K39: YUSUF ROBANI | L39: L
A41: L | B41: =COUNTIF(E10:E38,"L") -> 16 | D41: Luragung, 14 Juli 2025 | H41: L | I41: =COUNTIF(L10:L39,"L") -> 16 | K41: Luragung, 14 Juli 2025
A42: P | B42: =COUNTIF(E10:E38,"P") -> 13 | D42: Wali Kelas, | H42: P | I42: =COUNTIF(L10:L39,"P") -> 14 | K42: Wali Kelas,
D44: MAYAMUNAH, S.Pd | K44: RUKMINI, S.Pd
D45: NINTP. 6114 19890817 3 001 | K45: NIP. 19920303 202221 2 028
A46: PEMERINTAH DAERAH KABUPATEN KUNINGAN | H46: PEMERINTAH DAERAH KABUPATEN KUNINGAN
A47: DINAS PENDIDIKAN DAN KEBUDAYAAN | H47: DINAS PENDIDIKAN DAN KEBUDAYAAN
A48: SMPN 3 LURAGUNG | H48: SMPN 3 LURAGUNG
A49: Alamat : Jln. Abdi Praja No.01 Gunungkarung - Luragung | H49: Alamat : Jln. Abdi Praja No.01 Gunungkarung - Luragung
A51: ABSENSI KELAS VIII C | H51: ABSENSI KELAS VIII D
A52: TAHUN PELAJARAN 2025/2026 | H52: TAHUN PELAJARAN 2025/2026
A54: NO | B54: NIPD | C54: NISN | D54: NAMA PESERTA DIDIK | E54: JK | F54: KET | H54: NO | I54: NIPD | J54: NISN | K54: NAMA PESERTA DIDIK | L54: JK | M54: KET
A55: 1 | B55: 242507030 | C55: 0105657641 | D55: ABDAN HADABI | E55: L | H55: 1 | I55: 242507031 | J55: 0111513619 | K55: ADITYA NURDIANSYAH | L55: L
A56: 2 | B56: 242507059 | C56: 0103689556 | D56: ABIZHAR MUKLIS | E56: L | H56: 2 | I56: 242507003 | J56: 0116446794 | K56: ARISKA MAULIDAH | L56: P
A57: 3 | B57: 242507001 | C57: 0123165388 | D57: AISYAH KHAILA PUTRI | E57: P | H57: 3 | I57: 242507091 | J57: 0125269130 | K57: AZKA PRATAMA | L57: L
A58: 4 | B58: 242507089 | C58: 0108934459 | D58: ALDI DWI PUTRA | E58: L | H58: 4 | I58: 242507004 | J58: 0116892309 | K58: BANU KHAERUL FAHMI | L58: L
A59: 5 | B59: 242507002 | C59: 0125635380 | D59: AKBAR MAULANA BAHARUL ILMI | E59: L | H59: 5 | I59: 242507062 | J59: 0118619633 | K59: DILA SITI PADILAH PITRIAH | L59: P
A60: 6 | B60: 242507035 | C60: 0121971370 | D60: AMANDA DENIA SHAFA | E60: P | H60: 6 | I60: 242507064 | J60: 0115815284 | K60: ELIS EVILIA NATASHA | L60: P
A61: 7 | B61: 242507037 | C61: 0118707294 | D61: ANNISA KAELA SABRINA | E61: P | H61: 7 | I61: 242507094 | J61: 0119930339 | K61: FIRLY PRATAMA | L61: L
A62: 8 | B62: 242507092 | C62: 0115984431 | D62: DEDI PAHRUL RIADI | E62: L | H62: 8 | I62: 242507095 | J62: 0126343933 | K62: GINA ALINDA PUTRI | L62: P
...

Sheet IX
A1: PEMERINTAH DAERAH KABUPATEN KUNINGAN | H1: PEMERINTAH DAERAH KABUPATEN KUNINGAN
A2: DINAS PENDIDIKAN DAN KEBUDAYAAN | H2: DINAS PENDIDIKAN DAN KEBUDAYAAN
A3: SMPN 3 LURAGUNG | H3: SMPN 3 LURAGUNG
A4: Alamat : Jln. Abdi Praja No.01 Gunungkarung - Luragung | H4: Alamat : Jln. Abdi Praja No.01 Gunungkarung - Luragung
A6: ABSENSI KELAS IX A | H6: ABSENSI KELAS IX B
A7: TAHUN PELAJARAN 2025/2026 | H7: TAHUN PELAJARAN 2025/2026
A9: NO | B9: NIPD | C9: NISN | D9: NAMA PESERTA DIDIK | E9: JK | F9: KET | H9: NO | I9: NIPD | J9: NISN | K9: NAMA PESERTA DIDIK | L9: JK | M9: KET
A10: 1 | B10: 232407001 | C10: 0106675423 | D10: ADE HIDAYATUL HIARI | E10: L | H10: 1 | I10: 232407002 | J10: 0116527375 | K10: ADE IRFAN NUGRAHA | L10: L
A11: 2 | B11: 232407005 | C11: 0102582580 | D11: ALIN OKTAVIANI | E11: P | H11: 2 | I11: 232407028 | J11: 0106130407 | K11: AGUS SULAEMAN | L11: L
A12: 3 | B12: 232407057 | C12: 0107940154 | D12: ALVINO OKTA SAPUTRA | E12: L | H12: 3 | I12: 232407061 | J12: 0105129193 | K12: AULIA SINTIA BELA | L12: P
A13: 4 | B13: 232407058 | C13: 0102859627 | D13: ANDIKA SEPTIAN BASUKI PUTRA | E13: L | H13: 4 | I13: 232407086 | J13: 0117037248 | K13: AZKA NOR AZKIA | L13: L
A14: 5 | B14: 232407087 | C14: 0117040481 | D14: AZZAHRA SHINTA BELA | E14: P | H14: 5 | I14: 232407089 | J14: 0108493422 | K14: CANDRA ALFIANSYAH | L14: L
A15: 6 | B15: 232407008 | C15: 0111602468 | D15: DANU MERIYANA | E15: L | H15: 6 | I15: 232407007 | J15: 0106885471 | K15: DAFA AGNI MAULANA | L15: L
A16: 7 | B16: 232407009 | C16: 0107152402 | D16: DENIS RAMDHANI | E16: L | H16: 7 | I16: 232407090 | J16: 0105806849 | K16: DEVIRA MAESYA RAHMANI | L16: P
A17: 8 | B17: 232407034 | C17: 0103606335 | D17: DIAZ SEPTIAN AL - MAZID | E17: L | H17: 8 | I17: 232407037 | J17: 0103804750 | K17: ELA PUSPITA SARI | L17: P
A18: 9 | B18: 232407063 | C18: 0108924924 | D18: DIDIN JAENUDIN | E18: L | H18: 9 | I18: 232407038 | J18: 0102936373 | K18: ELSA AULIA | L18: P
A19: 10 | B19: 232407039 | C19: 0103746062 | D19: ERIK SETIAWAN RAMADHAN | E19: L | H19: 10 | I19: 232407095 | J19: 0096428127 | K19: HARUN PADILAH | L19: L
A20: 11 | B20: 232407066 | C20: 0109591594 | D20: GALUH GADA PRATAMA | E20: L | H20: 11 | I20: 232407097 | J20: 0116637721 | K20: ILAH ROHILAH | L20: P
A21: 12 | B21: 232407067 | C21: 0104114288 | D21: GILANG RAMADHAN | E21: L | H21: 12 | I21: 232407042 | J21: 0109953156 | K21: JAENAL ARIP | L21: L
... A36: 27 | B36: 232407111 | C36: 0106516789 | D36: WIDA KURNIASIH | E36: P | H36: 27 | I36: 232407056 | J36: 3113741281 | K36: TRIA FEBRIANA | L36: L
A37: 28 | B37: 252609108 | D37: REYFAN ALAM ARDIYANSYAH | E37: L | H37: 28 | I37: 232407113 | J37: 0119575649 | K37: WULAN DARA ASTUTI | L37: P
A39: L | B39: =COUNTIF(E10:E37,"L") -> 16 | D39: Luragung, 14 Juli 2025 | H39: L | I39: =COUNTIF(L10:L37,"L") -> 16 | K39: Luragung, 14 Juli 2025
A40: P | B40: =COUNTIF(E10:E37,"P") -> 12 | D40: Wali Kelas, | H40: P | I40: =COUNTIF(L10:L37,"P") -> 12 | K40: Wali Kelas,
D42: ASEP KURNAEPI, S.Pd., Gr | K42: MOMON, S.Pd.
D43: NINTP. 6114 19880120 3 002 | K43: NIP. 19700406 202121 1 001
A44: PEMERINTAH DAERAH KABUPATEN KUNINGAN | H44: PEMERINTAH DAERAH KABUPATEN KUNINGAN
A45: DINAS PENDIDIKAN DAN KEBUDAYAAN | H45: DINAS PENDIDIKAN DAN KEBUDAYAAN
A46: SMPN 3 LURAGUNG | H46: SMPN 3 LURAGUNG
A47: Alamat : Jln. Abdi Praja No.01 Gunungkarung - Luragung | H47: Alamat : Jln. Abdi Praja No.01 Gunungkarung - Luragung
A49: ABSENSI KELAS IX C | H49: ABSENSI KELAS IX D
A50: TAHUN PELAJARAN 2025/2026 | H50: TAHUN PELAJARAN 2025/2026
A52: NO | B52: NIPD | C52: NISN | D52: NAMA PESERTA DIDIK | E52: JK | F52: KET | H52: NO | I52: NIPD | J52: NISN | K52: NAMA PESERTA DIDIK | L52: JK | M52: KET
A53: 1 | B53: 232407059 | C53: 0101768178 | D53: ANISA SUCI RAMADANI | E53: P | H53: 1 | I53: 232407003 | J53: 0106497372 | K53: ADE WALIUDIN | L53: L
A54: 2 | B54: 232407060 | C54: 0108713156 | D54: ARMANSYAH | E54: L | H54: 2 | I54: 232407004 | J54: 0094789974 | K54: AIRIN DWI OKTAVIANI | L54: P
A55: 3 | B55: 232407085 | C55: 3094153140 | D55: AYATULLOH HAQQANI AFFAN | E55: L | H55: 3 | I55: 232407029 | J55: 0109821776 | K55: AKBAR OKTA PRANATA | L55: L
A56: 4 | B56: 232407006 | C56: 0108599519 | D56: DADAN HAMDANU | E56: L | H56: 4 | I56: 232407030 | J56: 0102839081 | K56: ALIEF RACHMANSYAH | L56: L
A57: 5 | B57: 232407010 | C57: 0092037574 | D57: DENNY KURNIAWAN | E57: L | H57: 5 | I57: 232407031 | J57: 0102777914 | K57: ANGGITA | L57: P
A58: 6 | B58: 232407033 | C58: 0109753402 | D58: DHAFA FARIZ ALFARIZY | E58: L | H58: 6 | I58: 232407032 | J58: 0103369435 | K58: ANISA NURPALAH | L58: P
A59: 7 | B59: 232407062 | C59: 0106953865 | D59: DIAZ DWI PUTRA | E59: L | H59: 7 | I59: 232407091 | J59: 0105324208 | K59: DIANA AULIA HASANAH | L59: P
A60: 8 | B60: 232407036 | C60: 0102866461 | D60: DIRLI TRI SETIAWAN | E60: L | H60: 8 | I60: 232407035 | J60: 0109568682 | K60: DINAR AULIA NURJANAH | L60: P
...

Sheet Rekap
A1: DATA JUMLAH SISWA
A2: TAHUN PELAJARAN 2025/2026
A4: KELAS | B4: L | C4: P | D4: JUMLAH | F4: JUMLAH | H4: JUMLAH KESELURUHAN
A5: VII A | B5: =VII!B37 -> 13 | C5: =VII!B38 -> 12 | D5: =SUM(B5:C5) -> 25 | F5: L | G5: P | H5: L+P
A6: VII B | B6: =VII!I37 -> 15 | C6: =VII!I38 -> 11 | D6: =SUM(B6:C6) -> 26 | F6: =B9+B16+B23 -> 187 | G6: =C9+C16+C23 -> 148 | H6: =D9+D16+D23 -> 335
A7: VII C | B7: =VII!B79 -> 15 | C7: =VII!B80 -> 12 | D7: =SUM(B7:C7) -> 27
A8: VII D | B8: =VII!I79 -> 15 | C8: =VII!B80 -> 12 | D8: =SUM(B8:C8) -> 27
A9: JUMLAH | B9: =SUM(B5:B8) -> 58 | C9: =SUM(C5:C8) -> 47 | D9: =SUM(D5:D8) -> 105
A11: KELAS | B11: L | C11: P | D11: JUMLAH
A12: VIII A | B12: =VIII!B41 -> 16 | C12: =VIII!B42 -> 13 | D12: =SUM(B12:C12) -> 29
A13: VIII B | B13: =VIII!I41 -> 16 | C13: =VIII!I42 -> 14 | D13: =SUM(B13:C13) -> 30
A14: VIII C | B14: =VIII!B85 -> 16 | C14: =VIII!B86 -> 13 | D14: =SUM(B14:C14) -> 29
A15: VIII D | B15: =VIII!I85 -> 17 | C15: =VIII!I86 -> 12 | D15: =SUM(B15:C15) -> 29
A16: JUMLAH | B16: =SUM(B12:B15) -> 65 | C16: =SUM(C12:C15) -> 52 | D16: =SUM(D12:D15) -> 117
A18: KELAS | B18: L | C18: P | D18: JUMLAH
A19: IX A | B19: =IX!B39 -> 16 | C19: =IX!B40 -> 12 | D19: =SUM(B19:C19) -> 28
A20: IX B | B20: =IX!I39 -> 16 | C20: =IX!I40 -> 12 | D20: =SUM(B20:C20) -> 28
A21: IX C | B21: =IX!B83 -> 16 | C21: =IX!B84 -> 12 | D21: =SUM(B21:C21) -> 28
A22: IX D | B22: =IX!I83 -> 16 | C22: =IX!I84 -> 13 | D22: =SUM(B22:C22) -> 29
A23: JUMLAH | B23: =SUM(B19:B22) -> 64 | C23: =SUM(C19:C22) -> 49 | D23: =SUM(D19:D22) -> 113
